<?xml version="1.0" encoding="utf-8"?>
<!-- This URDF was automatically created by SolidWorks to URDF Exporter! Originally created by Stephen Brawner (brawner@gmail.com) 
     Commit Version: 1.6.0-4-g7f85cfe  Build Version: 1.6.7995.38578
     For more information, please see http://wiki.ros.org/sw_urdf_exporter -->
<robot
  name="robotic_arm">
  <link
    name="base_link">
    <inertial>
      <origin xyz="0 0 0" rpy="0 0 0"/>
      <mass value="0.001"/>
      <inertia
        ixx="1e-6" ixy="0" ixz="0"
        iyy="1e-6" iyz="0"
        izz="1e-6"/>
    </inertial>
    <visual>
      <origin
        xyz="0 0 0"
        rpy="-1.5708 0 0" />
      <geometry>
        <mesh
          filename="package://robotic_arm/meshes/base_link.STL" />
      </geometry>
      <material
        name="">
        <color
          rgba="0.79216 0.81961 0.93333 1" />
      </material>
    </visual>
    <collision>
      <origin
        xyz="0 0 0"
        rpy="0 0 0" />
      <geometry>
        <mesh
          filename="package://robotic_arm/meshes/base_link.STL" />
      </geometry>
    </collision>
  </link>
  <gazebo reference="base_link" >
    <static>true</static>
  </gazebo>
  <link
    name="capstan_drive">
    <inertial>
      <origin
        xyz="-0.00010871 6.7353E-06 -0.017028"
        rpy="0 0 0" />
      <mass
        value="0.25255" />
      <inertia
        ixx="0.0001509"
        ixy="-2.9002E-09"
        ixz="4.457E-07"
        iyy="0.00015005"
        iyz="-5.7669E-09"
        izz="0.00025311" />
    </inertial>
    <visual>
      <origin
        xyz="0 0 -0.049"
        rpy="1.5708 0 0" />
      <geometry>
        <mesh
          filename="package://robotic_arm/meshes/capstan_drive.STL" />
      </geometry>
      <material
        name="">
        <color
          rgba="0.79216 0.81961 0.93333 1" />
      </material>
    </visual>
    <collision>
      <origin
        xyz="0 0 0"
        rpy="0 0 0" />
      <geometry>
        <mesh
          filename="package://robotic_arm/meshes/capstan_drive.STL" />
      </geometry>
    </collision>
  </link>
  <joint
    name="base_capstan"
    type="fixed">
    <origin
      xyz="0 0 0.0395"
      rpy="0 0 0" />
    <parent
      link="base_link" />
    <child
      link="capstan_drive" />
    <axis
      xyz="0 0 0" />
  </joint>
  <link
    name="arm_base">
    <inertial>
      <origin
        xyz="-0.012584 -0.0065009 0.032254"
        rpy="0 0 0" />
      <mass
        value="0.70947" />
      <inertia
        ixx="0.0011099"
        ixy="-1.8074E-07"
        ixz="-0.00010562"
        iyy="0.0016516"
        iyz="1.4831E-07"
        izz="0.0023602" />
    </inertial>
    <visual>
      <origin
        xyz="0 -0.09 -0.06"
        rpy="1.5708 0 -1.5708" />
      <geometry>
        <mesh
          filename="package://robotic_arm/meshes/arm_base.STL" />
      </geometry>
      <material
        name="">
        <color
          rgba="0.79216 0.81961 0.93333 1" />
      </material>
    </visual>
    <collision>
      <origin
        xyz="0 0 0"
        rpy="0 0 0" />
      <geometry>
        <mesh
          filename="package://robotic_arm/meshes/arm_base.STL" />
      </geometry>
    </collision>
  </link>
  <joint
    name="capstan_arm"
    type="revolute">
    <origin
      xyz="-0.088248 0.00055748 0.008"
      rpy="0 0 1.5894" />
    <parent
      link="capstan_drive" />
    <child
      link="arm_base" />
    <axis
      xyz="0 0 -1" />
    <limit
      lower="-1.4"
      upper="1.4"
      effort="36"
      velocity="0.2" />
  </joint>
  <link
    name="arm_link_1">
    <inertial>
      <origin
        xyz="1.3878E-17 -0.00051908 0.31703"
        rpy="0 0 0" />
      <mass
        value="1.9995" />
      <inertia
        ixx="0.012287"
        ixy="-6.7763E-20"
        ixz="-2.1344E-18"
        iyy="0.012814"
        iyz="3.6575E-05"
        izz="0.0015327" />
    </inertial>
    <visual>
      <origin
        xyz="0.09 0 -0.16"
        rpy="1.5708 0 0" />
      <geometry>
        <mesh
          filename="package://robotic_arm/meshes/arm_link_1.STL" />
      </geometry>
      <material
        name="">
        <color
          rgba="0.79216 0.81961 0.93333 1" />
      </material>
    </visual>
    <collision>
      <origin
        xyz="0 0 0"
        rpy="0 0 0" />
      <geometry>
        <mesh
          filename="package://robotic_arm/meshes/arm_link_1.STL" />
      </geometry>
    </collision>
  </link>
  <joint
    name="base_arm_rot"
    type="revolute">
    <origin
      xyz="-0.0072956 0 0.1"
      rpy="0 0.00035591 -1.5708" />
    <parent
      link="arm_base" />
    <child
      link="arm_link_1" />
    <axis
      xyz="0 -1 0" />
    <limit
      lower="-0.5"
      upper="1.35"
      effort="25"
      velocity="0.1" />
  </joint>
  <link name="arm_link_1_helper">
  <inertial>
    <origin xyz="0 0 0" rpy="0 0 0"/>
    <mass value="0.001"/>  <!-- Small mass to avoid issues -->
    <inertia ixx="1e-6" ixy="0" ixz="0" iyy="1e-6" iyz="0" izz="1e-6"/>
  </inertial>
  <visual>
    <origin xyz="0 0 0" rpy="0 0 0"/>
    <geometry>
      <box size="0.01 0.01 0.01"/>  <!-- Small invisible cube -->
    </geometry>
    <material name="black"/>
  </visual>
</link>
  <joint
    name="arm_elbow_roll"
    type="revolute">
    <origin
      xyz="4.1173E-05 0.005238 0.62096"
      rpy="0.0068467 -0.00071181 0" />
    <parent
      link="arm_link_1" />
    <child
      link="arm_link_1_helper" />
    <axis
      xyz="0 1 0" />
    <limit
      lower="-0.5"
      upper="0.5"
      effort="12"
      velocity="0.15" />
  </joint>
  <link
    name="arm_link_2">
    <inertial>
      <origin
        xyz="-1.3878E-17 -0.0079993 0.24635"
        rpy="0 0 0" />
      <mass
        value="1.0306" />
      <inertia
        ixx="0.0063388"
        ixy="1.0842E-19"
        ixz="-1.5675E-19"
        iyy="0.0071309"
        iyz="-6.364E-05"
        izz="0.0011923" />
    </inertial>
    <visual>
      <origin
        xyz="0.084 0 -0.77"
        rpy="1.5708 0 0" />
      <geometry>
        <mesh
          filename="package://robotic_arm/meshes/arm_link_2.STL" />
      </geometry>
      <material
        name="">
        <color
          rgba="0.79216 0.81961 0.93333 1" />
      </material>
    </visual>
    <collision>
      <origin
        xyz="0 0 0"
        rpy="0 0 0" />
      <geometry>
        <mesh
          filename="package://robotic_arm/meshes/arm_link_2.STL" />
      </geometry>
    </collision>
  </link>
  <joint
    name="arm_elbow"
    type="revolute">
    <origin
      xyz="4.1173E-05 0.005238 0.1"
      rpy="0.0068467 -0.00071181 0" />
    <parent
      link="arm_link_1_helper" />
    <child
      link="arm_link_2" />
    <axis
      xyz="0 1 0" />
    <limit
      lower="-1.4"
      upper="1.4"
      effort="12"
      velocity="0.15" />
  </joint>

  
</robot>