<?xml version="1.0" encoding="utf-8"?>
<!-- This URDF was automatically created by SolidWorks to URDF Exporter! Originally created by Stephen Brawner (brawner@gmail.com) 
     Commit Version: 1.6.0-4-g7f85cfe  Build Version: 1.6.7995.38578
     For more information, please see http://wiki.ros.org/sw_urdf_exporter -->
<robot
  name="robotic_arm_1">
  <link
    name="arm_base_link">
    <inertial>
      <origin
        xyz="-0.00010245634218275 2.45859996157774E-06 0.0214724928778274"
        rpy="0 0 0" />
      <mass
        value="0.252551886669556" />
      <inertia
        ixx="0.000150902038596133"
        ixy="-2.88436689650817E-09"
        ixz="4.39682919984636E-07"
        iyy="0.000150053189033015"
        iyz="-3.07792916448405E-09"
        izz="0.000253108560055644" />
    </inertial>
    <visual>
      <origin
        xyz="0 0 0"
        rpy="1.5708 0 0" />
      <geometry>
        <mesh
          filename="package://robotic_arm_1/meshes/arm_base_link.STL" />
      </geometry>
      <material
        name="">
        <color
          rgba="0.792156862745098 0.819607843137255 0.933333333333333 1" />
      </material>
    </visual>
    <collision>
      <origin
        xyz="0 0 0"
        rpy="0 0 0" />
      <geometry>
        <mesh
          filename="package://robotic_arm_1/meshes/arm_base_link.STL" />
      </geometry>
    </collision>
  </link>
  <link
    name="Capstan_arm_link">
    <inertial>
      <origin
        xyz="0.0070643032220165 -0.0122764637999162 0.0362543103918512"
        rpy="0 0 0" />
      <mass
        value="0.709466626058235" />
      <inertia
        ixx="0.00165051336508958"
        ixy="2.46957606770886E-05"
        ixz="4.63627043374479E-06"
        iyy="0.00111101449924064"
        iyz="-0.000105517085889965"
        izz="0.00236018957372939" />
    </inertial>
    <visual>
      <origin
        xyz="0.09 0 -0.06"
        rpy="1.5708 0 -1.5708" />
      <geometry>
        <mesh
          filename="package://robotic_arm_1/meshes/Capstan_arm_link.STL" />
      </geometry>
      <material
        name="">
        <color
          rgba="0.792156862745098 0.819607843137255 0.933333333333333 1" />
      </material>
    </visual>
    <collision>
      <origin
        xyz="0 0 0"
        rpy="0 0 0" />
      <geometry>
        <mesh
          filename="package://robotic_arm_1/meshes/Capstan_arm_link.STL" />
      </geometry>
    </collision>
  </link>
  <joint
    name="Joint_1_Capstan"
    type="revolute">
    <origin
      xyz="-0.08825 0 0.0435"
      rpy="0 0 -0.045315" />
    <parent
      link="arm_base_link" />
    <child
      link="Capstan_arm_link" />
    <axis
      xyz="0 0 -1" />
    <limit
      lower="-1.4"
      upper="1.4"
      effort="36"
      velocity="0.2" />
  </joint>
  <link
    name="arm_link_1">
    <inertial>
      <origin
        xyz="-1.90466102472087E-05 -0.00074067503085362 0.312950666881576"
        rpy="0 0 0" />
      <mass
        value="2.02559987896371" />
      <inertia
        ixx="0.0122955056364337"
        ixy="1.37460312510447E-05"
        ixz="-9.58057581347945E-07"
        iyy="0.012829700926555"
        iyz="-3.72564629302058E-05"
        izz="0.00154118844811022" />
    </inertial>
    <visual>
      <origin
        xyz="0.09 0 -0.16"
        rpy="1.5708 0 -1.5708" />
      <geometry>
        <mesh
          filename="package://robotic_arm_1/meshes/arm_link_1.STL" />
      </geometry>
      <material
        name="">
        <color
          rgba="0.792156862745098 0.819607843137255 0.933333333333333 1" />
      </material>
    </visual>
    <collision>
      <origin
        xyz="0 0 0"
        rpy="0 0 0" />
      <geometry>
        <mesh
          filename="package://robotic_arm_1/meshes/arm_link_1.STL" />
      </geometry>
    </collision>
  </link>
  <joint
    name="arm_link_1"
    type="revolute">
    <origin
      xyz="0.0001812 -0.0039959 0.104"
      rpy="0 0 0.071024" />
    <parent
      link="Capstan_arm_link" />
    <child
      link="arm_link_1" />
    <axis
      xyz="-0.025707 -0.99967 0" />
    <limit
      lower="-0.5"
      upper="1.4"
      effort="25"
      velocity="0.1" />
  </joint>
  <link
    name="arm_link_2">
    <inertial>
      <origin
        xyz="-3.23352455922077E-15 0.00799925604693499 0.246348425307334"
        rpy="0 0 0" />
      <mass
        value="1.03057802437217" />
      <inertia
        ixx="0.00633876312594691"
        ixy="-4.16173532851258E-19"
        ixz="-5.83484875325359E-19"
        iyy="0.00713091971056394"
        iyz="6.36398687437939E-05"
        izz="0.00119228700277233" />
    </inertial>
    <visual>
      <origin
        xyz="0.091 0 -0.9"
        rpy="1.5708 0 -1.5708" />
      <geometry>
        <mesh
          filename="package://robotic_arm_1/meshes/arm_link_2.STL" />
      </geometry>
      <material
        name="">
        <color
          rgba="0.792156862745098 0.819607843137255 0.933333333333333 1" />
      </material>
    </visual>
    <collision>
      <origin
        xyz="0 0 0"
        rpy="0 0 0" />
      <geometry>
        <mesh
          filename="package://robotic_arm_1/meshes/arm_link_2.STL" />
      </geometry>
    </collision>
  </link>
  <joint
    name="arm_link_2"
    type="revolute">
    <origin
      xyz="-0.0001928 -0.0074975 0.73665"
      rpy="0 0 -0.02571" />
    <parent
      link="arm_link_1" />
    <child
      link="arm_link_2" />
    <axis
      xyz="0 -1 0" />
    <limit
      lower="-1.4"
      upper="1.4"
      effort="12"
      velocity="0.15" />
  </joint>
</robot>